<?xml version="1.0" ?>
<robot name="five_dof_robot_arm" xmlns:xacro="http://www.ros.org/wiki/xacro">

<xacro:include filename="$(find five_dof_robot_arm_description)/urdf/materials.xacro" />
<xacro:include filename="$(find five_dof_robot_arm_description)/urdf/five_dof_robot_arm.trans" />
<xacro:include filename="$(find five_dof_robot_arm_description)/urdf/five_dof_robot_arm.gazebo" />
<link name="base_link">
  <inertial>
    <origin xyz="0.0008893073972662709 0.022425917284170566 2.4674686335974806e-17" rpy="0 0 0"/>
    <mass value="0.7233661769499682"/>
    <inertia ixx="0.000878" iyy="0.001522" izz="0.000958" ixy="-1e-05" iyz="-0.0" ixz="-0.0"/>
  </inertial>
  <visual>
    <origin xyz="0 0 0" rpy="0 0 0"/>
    <geometry>
      <mesh filename="file://$(find five_dof_robot_arm_description)/meshes/base_link.stl" scale="0.001 0.001 0.001"/>
    </geometry>
    <material name="silver"/>
  </visual>
  <collision>
    <origin xyz="0 0 0" rpy="0 0 0"/>
    <geometry>
      <mesh filename="file://$(find five_dof_robot_arm_description)/meshes/base_link.stl" scale="0.001 0.001 0.001"/>
    </geometry>
  </collision>
</link>

<link name="link1_1">
  <inertial>
    <origin xyz="-0.007057739507975238 0.01942304389081126 -1.3071147422228935e-08" rpy="0 0 0"/>
    <mass value="0.7043175850391776"/>
    <inertia ixx="0.000607" iyy="0.000555" izz="0.000525" ixy="6.3e-05" iyz="0.0" ixz="-0.0"/>
  </inertial>
  <visual>
    <origin xyz="-0.0 -0.05 -0.0" rpy="0 0 0"/>
    <geometry>
      <mesh filename="file://$(find five_dof_robot_arm_description)/meshes/link1_1.stl" scale="0.001 0.001 0.001"/>
    </geometry>
    <material name="silver"/>
  </visual>
  <collision>
    <origin xyz="-0.0 -0.05 -0.0" rpy="0 0 0"/>
    <geometry>
      <mesh filename="file://$(find five_dof_robot_arm_description)/meshes/link1_1.stl" scale="0.001 0.001 0.001"/>
    </geometry>
  </collision>
</link>

<link name="link2_1">
  <inertial>
    <origin xyz="0.01150846971338263 0.019996376907272073 -3.64164684560196e-07" rpy="0 0 0"/>
    <mass value="1.0831665493448956"/>
    <inertia ixx="0.003389" iyy="0.000242" izz="0.003241" ixy="0.0" iyz="0.0" ixz="0.0"/>
  </inertial>
  <visual>
    <origin xyz="0.0025 -0.14355 -0.0" rpy="0 0 0"/>
    <geometry>
      <mesh filename="file://$(find five_dof_robot_arm_description)/meshes/link2_1.stl" scale="0.001 0.001 0.001"/>
    </geometry>
    <material name="silver"/>
  </visual>
  <collision>
    <origin xyz="0.0025 -0.14355 -0.0" rpy="0 0 0"/>
    <geometry>
      <mesh filename="file://$(find five_dof_robot_arm_description)/meshes/link2_1.stl" scale="0.001 0.001 0.001"/>
    </geometry>
  </collision>
</link>

<link name="link3_1">
  <inertial>
    <origin xyz="-0.24532894023458857 0.10039894186396298 0.00010054306897835837" rpy="0 0 0"/>
    <mass value="0.630632827570374"/>
    <inertia ixx="0.00092" iyy="0.000167" izz="0.00082" ixy="6e-06" iyz="-2e-06" ixz="0.0"/>
  </inertial>
  <visual>
    <origin xyz="-0.23225 -0.16485 -0.0" rpy="0 0 0"/>
    <geometry>
      <mesh filename="file://$(find five_dof_robot_arm_description)/meshes/link3_1.stl" scale="0.001 0.001 0.001"/>
    </geometry>
    <material name="silver"/>
  </visual>
  <collision>
    <origin xyz="-0.23225 -0.16485 -0.0" rpy="0 0 0"/>
    <geometry>
      <mesh filename="file://$(find five_dof_robot_arm_description)/meshes/link3_1.stl" scale="0.001 0.001 0.001"/>
    </geometry>
  </collision>
</link>

<link name="link4_1">
  <inertial>
    <origin xyz="0.3294176513903725 0.1091129813639905 -0.004589286491915792" rpy="0 0 0"/>
    <mass value="0.1604066490426529"/>
    <inertia ixx="4.8e-05" iyy="2.3e-05" izz="4e-05" ixy="-3e-06" iyz="-0.0" ixz="-0.0"/>
  </inertial>
  <visual>
    <origin xyz="0.33905 -0.2479 -0.0051" rpy="0 0 0"/>
    <geometry>
      <mesh filename="file://$(find five_dof_robot_arm_description)/meshes/link4_1.stl" scale="0.001 0.001 0.001"/>
    </geometry>
    <material name="silver"/>
  </visual>
  <collision>
    <origin xyz="0.33905 -0.2479 -0.0051" rpy="0 0 0"/>
    <geometry>
      <mesh filename="file://$(find five_dof_robot_arm_description)/meshes/link4_1.stl" scale="0.001 0.001 0.001"/>
    </geometry>
  </collision>
</link>

<link name="link5_1">
  <inertial>
    <origin xyz="0.3811951162503874 0.05234257335770304 0.005895868370981221" rpy="0 0 0"/>
    <mass value="0.12228249757136996"/>
    <inertia ixx="3.8e-05" iyy="2e-05" izz="4.9e-05" ixy="4e-06" iyz="-7e-06" ixz="0.0"/>
  </inertial>
  <visual>
    <origin xyz="0.380696 -0.339091 0.000563" rpy="0 0 0"/>
    <geometry>
      <mesh filename="file://$(find five_dof_robot_arm_description)/meshes/link5_1.stl" scale="0.001 0.001 0.001"/>
    </geometry>
    <material name="silver"/>
  </visual>
  <collision>
    <origin xyz="0.380696 -0.339091 0.000563" rpy="0 0 0"/>
    <geometry>
      <mesh filename="file://$(find five_dof_robot_arm_description)/meshes/link5_1.stl" scale="0.001 0.001 0.001"/>
    </geometry>
  </collision>
</link>

<link name="link6_1">
  <inertial>
    <origin xyz="-0.035080190432956376 0.04740339370536095 -0.3812718159779585" rpy="0 0 0"/>
    <mass value="0.02217224627002088"/>
    <inertia ixx="1e-06" iyy="3e-06" izz="4e-06" ixy="1e-06" iyz="0.0" ixz="-0.0"/>
  </inertial>
  <visual>
    <origin xyz="-0.01478 -0.353104 -0.397691" rpy="0 0 0"/>
    <geometry>
      <mesh filename="file://$(find five_dof_robot_arm_description)/meshes/link6_1.stl" scale="0.001 0.001 0.001"/>
    </geometry>
    <material name="silver"/>
  </visual>
  <collision>
    <origin xyz="-0.01478 -0.353104 -0.397691" rpy="0 0 0"/>
    <geometry>
      <mesh filename="file://$(find five_dof_robot_arm_description)/meshes/link6_1.stl" scale="0.001 0.001 0.001"/>
    </geometry>
  </collision>
</link>

<link name="Link_1">
  <inertial>
    <origin xyz="-0.014229544435476919 0.006145403777810476 0.0020004660896868597" rpy="0 0 0"/>
    <mass value="0.006270284943499798"/>
    <inertia ixx="0.0" iyy="1e-06" izz="1e-06" ixy="0.0" iyz="-0.0" ixz="0.0"/>
  </inertial>
  <visual>
    <origin xyz="0.004946 -0.41715 -0.012675" rpy="0 0 0"/>
    <geometry>
      <mesh filename="file://$(find five_dof_robot_arm_description)/meshes/Link_1.stl" scale="0.001 0.001 0.001"/>
    </geometry>
    <material name="silver"/>
  </visual>
  <collision>
    <origin xyz="0.004946 -0.41715 -0.012675" rpy="0 0 0"/>
    <geometry>
      <mesh filename="file://$(find five_dof_robot_arm_description)/meshes/Link_1.stl" scale="0.001 0.001 0.001"/>
    </geometry>
  </collision>
</link>

<link name="grip_1">
  <inertial>
    <origin xyz="0.006505466490310481 0.02647864161703206 -0.004249533910313229" rpy="0 0 0"/>
    <mass value="0.04236978910676512"/>
    <inertia ixx="1.3e-05" iyy="1e-06" izz="1.3e-05" ixy="-2e-06" iyz="0.0" ixz="0.0"/>
  </inertial>
  <visual>
    <origin xyz="0.042119 -0.40924 -0.012675" rpy="0 0 0"/>
    <geometry>
      <mesh filename="file://$(find five_dof_robot_arm_description)/meshes/grip_1.stl" scale="0.001 0.001 0.001"/>
    </geometry>
    <material name="silver"/>
  </visual>
  <collision>
    <origin xyz="0.042119 -0.40924 -0.012675" rpy="0 0 0"/>
    <geometry>
      <mesh filename="file://$(find five_dof_robot_arm_description)/meshes/grip_1.stl" scale="0.001 0.001 0.001"/>
    </geometry>
  </collision>
</link>

<link name="grip_1">
  <inertial>
    <origin xyz="-0.0022085335096895184 0.006277641617032037 -0.004249533910313229" rpy="0 0 0"/>
    <mass value="0.04236978910676512"/>
    <inertia ixx="1.3e-05" iyy="1e-06" izz="1.3e-05" ixy="-2e-06" iyz="0.0" ixz="0.0"/>
  </inertial>
  <visual>
    <origin xyz="0.033405 -0.429441 -0.012675" rpy="0 0 0"/>
    <geometry>
      <mesh filename="file://$(find five_dof_robot_arm_description)/meshes/grip_1.stl" scale="0.001 0.001 0.001"/>
    </geometry>
    <material name="silver"/>
  </visual>
  <collision>
    <origin xyz="0.033405 -0.429441 -0.012675" rpy="0 0 0"/>
    <geometry>
      <mesh filename="file://$(find five_dof_robot_arm_description)/meshes/grip_1.stl" scale="0.001 0.001 0.001"/>
    </geometry>
  </collision>
</link>

<joint name="joint1" type="revolute">
  <origin xyz="0.0 0.05 0.0" rpy="0 0 0"/>
  <parent link="base_link"/>
  <child link="link1_1"/>
  <axis xyz="0.0 1.0 0.0"/>
  <limit upper="3.141593" lower="0.0" effort="100" velocity="100"/>
</joint>

<joint name="joint2" type="revolute">
  <origin xyz="-0.0025 0.09355 0.0" rpy="0 0 0"/>
  <parent link="link1_1"/>
  <child link="link2_1"/>
  <axis xyz="-1.0 -0.0 -0.0"/>
  <limit upper="1.570796" lower="-1.570796" effort="100" velocity="100"/>
</joint>

<joint name="joint3" type="revolute">
  <origin xyz="0.23475 0.0213 0.0" rpy="0 0 0"/>
  <parent link="link2_1"/>
  <child link="link3_1"/>
  <axis xyz="-1.0 -0.0 -0.0"/>
  <limit upper="1.570796" lower="-1.570796" effort="100" velocity="100"/>
</joint>

<joint name="joint4" type="revolute">
  <origin xyz="-0.5713 0.08305 0.0051" rpy="0 0 0"/>
  <parent link="link3_1"/>
  <child link="link4_1"/>
  <axis xyz="-0.0 1.0 0.0"/>
  <limit upper="3.141593" lower="0.0" effort="100" velocity="100"/>
</joint>

<joint name="joint5" type="revolute">
  <origin xyz="-0.041646 0.091191 -0.005663" rpy="0 0 0"/>
  <parent link="link4_1"/>
  <child link="link5_1"/>
  <axis xyz="-1.0 0.0 0.0"/>
  <limit upper="1.570796" lower="-1.570796" effort="100" velocity="100"/>
</joint>

<joint name="joint6" type="revolute">
  <origin xyz="0.395476 0.014013 0.398254" rpy="0 0 0"/>
  <parent link="link5_1"/>
  <child link="link6_1"/>
  <axis xyz="-0.0 -0.0 1.0"/>
  <limit upper="0.0" lower="-1.570796" effort="100" velocity="100"/>
</joint>

<joint name="Revolute 7" type="revolute">
  <origin xyz="0.37575 0.078059 0.013238" rpy="0 0 0"/>
  <parent link="link5_1"/>
  <child link="Link_1"/>
  <axis xyz="-0.0 -0.0 1.0"/>
  <limit upper="0.0" lower="-1.570796" effort="100" velocity="100"/>
</joint>

<joint name="Revolute 12" type="revolute">
  <origin xyz="-0.048185 0.076337 -0.385016" rpy="0 0 0"/>
  <parent link="link6_1"/>
  <child link="grip_1"/>
  <axis xyz="-0.0 0.0 -1.0"/>
  <limit upper="0.0" lower="-1.570796" effort="100" velocity="100"/>
</joint>

<joint name="Revolute 13" type="revolute">
  <origin xyz="-0.028459 0.012291 0.0" rpy="0 0 0"/>
  <parent link="Link_1"/>
  <child link="grip_1"/>
  <axis xyz="0.0 -0.0 1.0"/>
  <limit upper="1.570796" lower="0.0" effort="100" velocity="100"/>
</joint>

</robot>
